오류 발생 시각: 2025-09-23 10:35:02
오류 타입: ImageNotFoundException
오류 메시지: 
Traceback:
Traceback (most recent call last):
  File "/Users/suhyeon/miniforge3/lib/python3.12/site-packages/pyautogui/__init__.py", line 172, in wrapper
    return wrappedFunction(*args, **kwargs)
           ^^^^^^^^^^^^^^^^^^^^^^^^^^^^^^^^
  File "/Users/suhyeon/miniforge3/lib/python3.12/site-packages/pyautogui/__init__.py", line 204, in locateCenterOnScreen
    return pyscreeze.locateCenterOnScreen(*args, **kwargs)
           ^^^^^^^^^^^^^^^^^^^^^^^^^^^^^^^^^^^^^^^^^^^^^^^
  File "/Users/suhyeon/miniforge3/lib/python3.12/site-packages/pyscreeze/__init__.py", line 447, in locateCenterOnScreen
    coords = locateOnScreen(image, **kwargs)
             ^^^^^^^^^^^^^^^^^^^^^^^^^^^^^^^
  File "/Users/suhyeon/miniforge3/lib/python3.12/site-packages/pyscreeze/__init__.py", line 405, in locateOnScreen
    retVal = locate(image, screenshotIm, **kwargs)
             ^^^^^^^^^^^^^^^^^^^^^^^^^^^^^^^^^^^^^
  File "/Users/suhyeon/miniforge3/lib/python3.12/site-packages/pyscreeze/__init__.py", line 383, in locate
    points = tuple(locateAll(needleImage, haystackImage, **kwargs))
             ^^^^^^^^^^^^^^^^^^^^^^^^^^^^^^^^^^^^^^^^^^^^^^^^^^^^^^
  File "/Users/suhyeon/miniforge3/lib/python3.12/site-packages/pyscreeze/__init__.py", line 257, in _locateAll_opencv
    raise ImageNotFoundException('Could not locate the image (highest confidence = %.3f)' % result.max())
pyscreeze.ImageNotFoundException: Could not locate the image (highest confidence = 0.301)

During handling of the above exception, another exception occurred:

Traceback (most recent call last):
  File "/Users/suhyeon/Documents/code/python/kakaotalk_habangsi/test.py", line 24, in send_message
    chatroom_location = pyautogui.locateCenterOnScreen('chatroom_name.png', confidence=0.8)
                        ^^^^^^^^^^^^^^^^^^^^^^^^^^^^^^^^^^^^^^^^^^^^^^^^^^^^^^^^^^^^^^^^^^^
  File "/Users/suhyeon/miniforge3/lib/python3.12/site-packages/pyautogui/__init__.py", line 174, in wrapper
    raise ImageNotFoundException  # Raise PyAutoGUI's ImageNotFoundException.
    ^^^^^^^^^^^^^^^^^^^^^^^^^^^^
pyautogui.ImageNotFoundException

--------------------
오류 발생 시각: 2025-09-23 10:45:08
오류 타입: NameError
오류 메시지: name 'chatroom_location' is not defined
Traceback:
Traceback (most recent call last):
  File "/Users/suhyeon/Documents/code/python/kakaotalk_habangsi/test.py", line 42, in send_message
    pyautogui.click(chatroom_location) # fallback
                    ^^^^^^^^^^^^^^^^^
NameError: name 'chatroom_location' is not defined

--------------------
오류 발생 시각: 2025-09-23 10:49:07
오류 타입: NameError
오류 메시지: name 'chatroom_location' is not defined
Traceback:
Traceback (most recent call last):
  File "/Users/suhyeon/Documents/code/python/kakaotalk_habangsi/test.py", line 36, in send_message
    pyautogui.click(chatroom_location) # fallback
                    ^^^^^^^^^^^^^^^^^
NameError: name 'chatroom_location' is not defined

--------------------
오류 발생 시각: 2025-09-23 15:07:48
오류 타입: NameError
오류 메시지: name 'pypercip' is not defined
Traceback:
Traceback (most recent call last):
  File "/Users/suhyeon/Documents/code/python/kakaotalk_habangsi/test2.py", line 31, in prepare_messages
    pypercip.copy(CHATROOM_NAME)
    ^^^^^^^^
NameError: name 'pypercip' is not defined. Did you mean: 'pyperclip'?

--------------------
